<?xml version="1.0"?>
<robot xmlns:xacro="http://www.ros.org/wiki/xacro" name="rover">


<link name="base_footprint"/>

<!-- <xacro:property name="mass" value="1.0"/>
    <xacro:property name="weidth" value="0.8"/>
    <xacro:property name="height" value="0.1"/>
    <xacro:property name="depth" value="0.7"/>
    <xacro:property name="constant" value="1/12"/> 
-->

<link name="base_link">
    <inertial>
        <origin xyz="0.0 0.0 0.0" rpy="0.0 0.0 0.0"/>
        <mass value="1.0"/>
        <inertia ixx="0.04"  ixy="0.0" ixz="0.0"
                 iyy="0.05"  iyz="0.0"
                 izz="0.09"/>
    </inertial>
    <visual name="">
        <origin xyz="0.0 0.0 0.0" rpy="0.0 0.0 0.0"/>
        <geometry>
            <box size="0.8 0.66 0.1"/>
        </geometry>
        <material name="black">
            <color rgba="0.0 0.0 0.0 1.0"/>
            <texture filename=""/>
        </material>
    </visual>
    <collision name="base_link">
        <origin xyz="0.0 0.0 0.0" rpy="0.0 0.0 0.0"/>
        <geometry>
            <box size="0.7 0.6 0.05"/>
        </geometry>
    </collision>
    <sensor name="contact_sensor" type="contact">
        <update_rate>20.0</update_rate> 
    </sensor>
</link>

<joint name="base_joint" type="fixed">
    <origin xyz="0.0 0.0 0.05" rpy="0.0 0.0 0.0"/>
    <parent link="base_footprint"/>
    <child link="base_link"/>
    <axis xyz="0.0 0.0 0.0"/>
</joint>




<!-- Hokuyo Laser mounting platform -->

<link name="laser_mount">
    <inertial>
        <origin xyz="0.0 0.0 0.0" rpy="0.0 0.0 0.0"/> 
        <mass value="0.1"/> 
        <inertia ixx="0.001" ixy="0.0" ixz="0.0"
                 iyy="0.001" iyz="0.0"
                 izz="0.001"/> 
    </inertial>
    <visual>
        <origin xyz="0.0 0.0 0.0" rpy="0.0 0.0 0.0"/>
        <geometry>
            <box size="0.3 0.3 0.1"/> 
        </geometry>
        <material name="grey">
            <color rgba="0.5 0.5 0.5 1.0"/> 
        </material>
    </visual>
    <collision>
        <origin xyz="0.0 0.0 0.0" rpy="0.0 0.0 0.0"/>
        <geometry>
            <box size="0.28 0.28 0.08"/> 
        </geometry>
    </collision>
</link>
<joint name="laser_mount_joint" type="fixed">
    <origin xyz="0.0 0.0 0.1" rpy="0.0 0.0 0.0"/> <!-- Adjust the height (0.1 in this example) to match the platform's height -->
    <parent link="base_link"/> 
    <child link="laser_mount"/>
</joint>




<!-- Hokuyo Laser -->

  <link name="hokuyo_link">
    <collision>
      <origin xyz="0 0 0" rpy="0 0 0"/>
      <geometry>
        <box size="0.05 0.05 0.05"/>
      </geometry>
    </collision>

    <visual>
      <origin xyz="0 0 0" rpy="0 0 0"/>
      <geometry>
        <mesh filename="package://task_pkg/meshes/hokuyo.stl"/>
      </geometry>
      <material name="red">
        <color rgba="1.0 0.0 0.0 1.0"/>
      </material>
    </visual>

    <inertial>
      <mass value="1e-2" />
      <origin xyz="0 0 0" rpy="0 0 0"/>
      <inertia ixx="1e-6" ixy="0" ixz="0" iyy="1e-6" iyz="0" izz="1e-6" />
    </inertial>
  </link>

 <joint name="hokuyo_joint" type="fixed">
    <axis xyz="0 1 0" />
    <origin xyz="0 0 0.05" rpy="0 0 0"/>
    <parent link="laser_mount"/>
    <child link="hokuyo_link"/>
  </joint>




<!-- All Wheel links and joints -->

<xacro:macro name="wheel" params="pos_name stl_wheel_name x y">

    <link name="wheel_${pos_name}_link">
        <inertial>
            <origin xyz="0.0 0.0 0" rpy="0.0 0.0 0.0"/>
            <mass value="0.4"/>
            <inertia ixx="0.0" ixy="0.0" ixz="0.0" iyy="0.0" iyz="0.0" izz="0.0"/>
        </inertial>
        <visual name="">
            <origin xyz="0.0 0.0 0.0" rpy="0.0 0.0 0.0"/>
            <geometry>
                <mesh filename="package://task_pkg/meshes/${stl_wheel_name}.stl" scale="0.003 0.005 0.003"/>
            </geometry>
            <material name="yellow">
                <color rgba="1.0 1.0 0.0 1.0"/>
            </material>
        </visual>
        <collision name="wheel_${pos_name}_joint">
            <origin xyz="0.0 0.0 0.0" rpy="0.0 0.0 0.0"/>
            <geometry>
                <mesh filename="package://task_pkg/meshes/${stl_wheel_name}.stl" scale="0.002 0.004 0.002"/>
            </geometry>
        </collision>
        <sensor name="contact_sensor" type="contact">
            <update_rate>10.0</update_rate> 
        </sensor>
    </link>

    <joint name="wheel_${pos_name}_joint" type="continuous">
        <origin xyz="${x} ${y} 0.0" rpy="0 0.0 0.0"/>
        <parent link="base_link"/>
        <child link="wheel_${pos_name}_link"/>
        <axis xyz="0 1 0"/>
    </joint>

</xacro:macro>


<!-- Wheel Creating using macros -->
<xacro:wheel pos_name="front_right"  stl_wheel_name="right_tire" x="0.250"  y =" 0.40"/>
<xacro:wheel pos_name="rear_right" stl_wheel_name="right_tire" x="-0.250" y =" 0.40"/>
<xacro:wheel pos_name="rear_left"  stl_wheel_name="left_tire"  x="-0.250" y =" -0.40"/>
<xacro:wheel pos_name="front_left"   stl_wheel_name="left_tire"  x="0.250"  y =" -0.40"/>



<!-- including gazebo propertion for effective simulation -->
<xacro:include filename="gazebo_properties.xacro"/>



</robot>
